2022-05-12 06:23:55,446 DEBUG    root            Loaded Command Group: ['gcloud', 'services']
2022-05-12 06:23:55,453 DEBUG    root            Loaded Command Group: ['gcloud', 'services', 'enable']
2022-05-12 06:23:55,456 DEBUG    root            Running [gcloud.services.enable] with arguments: [SERVICE:1: "['containerregistry.googleapis.com']"]
2022-05-12 06:23:55,467 DEBUG    google.auth.transport.requests Making request: GET http://metadata.google.internal/computeMetadata/v1/instance/service-accounts/801727839795-compute@developer.gserviceaccount.com/?recursive=true
2022-05-12 06:23:55,469 DEBUG    urllib3.connectionpool Starting new HTTP connection (1): metadata.google.internal:80
2022-05-12 06:23:55,470 DEBUG    urllib3.connectionpool http://metadata.google.internal:80 "GET /computeMetadata/v1/instance/service-accounts/801727839795-compute@developer.gserviceaccount.com/?recursive=true HTTP/1.1" 200 197
2022-05-12 06:23:55,471 DEBUG    google.auth.transport.requests Making request: GET http://metadata.google.internal/computeMetadata/v1/instance/service-accounts/801727839795-compute@developer.gserviceaccount.com/token
2022-05-12 06:23:55,473 DEBUG    urllib3.connectionpool http://metadata.google.internal:80 "GET /computeMetadata/v1/instance/service-accounts/801727839795-compute@developer.gserviceaccount.com/token HTTP/1.1" 200 276
2022-05-12 06:23:55,573 DEBUG    urllib3.connectionpool Starting new HTTPS connection (1): serviceusage.googleapis.com:443
2022-05-12 06:23:57,301 DEBUG    urllib3.connectionpool https://serviceusage.googleapis.com:443 "POST /v1/projects/genuine-range-349802/services/containerregistry.googleapis.com:enable?alt=json HTTP/1.1" 403 None
2022-05-12 06:23:57,307 DEBUG    root            (gcloud.services.enable) PERMISSION_DENIED: Request had insufficient authentication scopes.
- '@type': type.googleapis.com/google.rpc.ErrorInfo
  domain: googleapis.com
  metadata:
    method: google.api.serviceusage.v1.ServiceUsage.EnableService
    service: serviceusage.googleapis.com
  reason: ACCESS_TOKEN_SCOPE_INSUFFICIENT
Traceback (most recent call last):
  File "/usr/lib64/google-cloud-sdk/lib/googlecloudsdk/api_lib/services/serviceusage.py", line 75, in EnableApiCall
    return client.services.Enable(request)
  File "/usr/lib64/google-cloud-sdk/lib/googlecloudsdk/third_party/apis/serviceusage/v1/serviceusage_v1_client.py", line 263, in Enable
    return self._RunMethod(
  File "/usr/lib64/google-cloud-sdk/lib/third_party/apitools/base/py/base_api.py", line 737, in _RunMethod
    return self.ProcessHttpResponse(method_config, http_response, request)
  File "/usr/lib64/google-cloud-sdk/lib/third_party/apitools/base/py/base_api.py", line 743, in ProcessHttpResponse
    self.__ProcessHttpResponse(method_config, http_response, request))
  File "/usr/lib64/google-cloud-sdk/lib/third_party/apitools/base/py/base_api.py", line 609, in __ProcessHttpResponse
    raise exceptions.HttpError.FromResponse(
apitools.base.py.exceptions.HttpForbiddenError: HttpError accessing <https://serviceusage.googleapis.com/v1/projects/genuine-range-349802/services/containerregistry.googleapis.com:enable?alt=json>: response: <{'www-authenticate': 'Bearer realm="https://accounts.google.com/", error="insufficient_scope", scope="https://www.googleapis.com/auth/service.management https://www.googleapis.com/auth/cloud-platform"', 'vary': 'Origin, X-Origin, Referer', 'content-type': 'application/json; charset=UTF-8', 'content-encoding': 'gzip', 'date': 'Thu, 12 May 2022 06:23:57 GMT', 'server': 'ESF', 'cache-control': 'private', 'x-xss-protection': '0', 'x-frame-options': 'SAMEORIGIN', 'x-content-type-options': 'nosniff', 'transfer-encoding': 'chunked', 'status': 403}>, content <{
  "error": {
    "code": 403,
    "message": "Request had insufficient authentication scopes.",
    "status": "PERMISSION_DENIED",
    "details": [
      {
        "@type": "type.googleapis.com/google.rpc.ErrorInfo",
        "reason": "ACCESS_TOKEN_SCOPE_INSUFFICIENT",
        "domain": "googleapis.com",
        "metadata": {
          "service": "serviceusage.googleapis.com",
          "method": "google.api.serviceusage.v1.ServiceUsage.EnableService"
        }
      }
    ]
  }
}
>

During handling of the above exception, another exception occurred:

Traceback (most recent call last):
  File "/usr/lib64/google-cloud-sdk/lib/googlecloudsdk/calliope/cli.py", line 987, in Execute
    resources = calliope_command.Run(cli=self, args=args)
  File "/usr/lib64/google-cloud-sdk/lib/googlecloudsdk/calliope/backend.py", line 809, in Run
    resources = command_instance.Run(args)
  File "/usr/lib64/google-cloud-sdk/lib/surface/services/enable.py", line 92, in Run
    op = serviceusage.EnableApiCall(project, args.service[0])
  File "/usr/lib64/google-cloud-sdk/lib/googlecloudsdk/api_lib/services/serviceusage.py", line 78, in EnableApiCall
    exceptions.ReraiseError(e,
  File "/usr/lib64/google-cloud-sdk/lib/googlecloudsdk/api_lib/services/exceptions.py", line 121, in ReraiseError
    core_exceptions.reraise(klass(api_lib_exceptions.HttpException(err)))
  File "/usr/lib64/google-cloud-sdk/lib/googlecloudsdk/core/exceptions.py", line 146, in reraise
    six.reraise(type(exc_value), exc_value, tb)
  File "/usr/lib64/google-cloud-sdk/lib/third_party/six/__init__.py", line 692, in reraise
    raise value.with_traceback(tb)
  File "/usr/lib64/google-cloud-sdk/lib/googlecloudsdk/api_lib/services/serviceusage.py", line 75, in EnableApiCall
    return client.services.Enable(request)
  File "/usr/lib64/google-cloud-sdk/lib/googlecloudsdk/third_party/apis/serviceusage/v1/serviceusage_v1_client.py", line 263, in Enable
    return self._RunMethod(
  File "/usr/lib64/google-cloud-sdk/lib/third_party/apitools/base/py/base_api.py", line 737, in _RunMethod
    return self.ProcessHttpResponse(method_config, http_response, request)
  File "/usr/lib64/google-cloud-sdk/lib/third_party/apitools/base/py/base_api.py", line 743, in ProcessHttpResponse
    self.__ProcessHttpResponse(method_config, http_response, request))
  File "/usr/lib64/google-cloud-sdk/lib/third_party/apitools/base/py/base_api.py", line 609, in __ProcessHttpResponse
    raise exceptions.HttpError.FromResponse(
googlecloudsdk.api_lib.services.exceptions.EnableServicePermissionDeniedException: PERMISSION_DENIED: Request had insufficient authentication scopes.
- '@type': type.googleapis.com/google.rpc.ErrorInfo
  domain: googleapis.com
  metadata:
    method: google.api.serviceusage.v1.ServiceUsage.EnableService
    service: serviceusage.googleapis.com
  reason: ACCESS_TOKEN_SCOPE_INSUFFICIENT
2022-05-12 06:23:57,317 ERROR    root            (gcloud.services.enable) PERMISSION_DENIED: Request had insufficient authentication scopes.
- '@type': type.googleapis.com/google.rpc.ErrorInfo
  domain: googleapis.com
  metadata:
    method: google.api.serviceusage.v1.ServiceUsage.EnableService
    service: serviceusage.googleapis.com
  reason: ACCESS_TOKEN_SCOPE_INSUFFICIENT
