2022-05-12 07:10:56,308 DEBUG    root            Loaded Command Group: ['gcloud', 'auth']
2022-05-12 07:10:56,311 DEBUG    root            Loaded Command Group: ['gcloud', 'auth', 'application_default']
2022-05-12 07:10:56,345 DEBUG    root            Loaded Command Group: ['gcloud', 'auth', 'application-default', 'login']
2022-05-12 07:10:56,349 DEBUG    root            Running [gcloud.auth.application-default.login] with arguments: []
2022-05-12 07:11:01,182 DEBUG    requests_oauthlib.oauth2_session Generated new state kZnlRO6sCkvrlcSZSz3vNK77cZAGfQ.
2022-05-12 07:11:01,183 INFO     ___FILE_ONLY___ You are authorizing client libraries without access to a web browser. Please run the following command on a machine with a web browser and copy its output back here. Make sure the installed gcloud version is 372.0.0 or newer.

gcloud auth application-default login --remote-bootstrap="https://accounts.google.com/o/oauth2/auth?response_type=code&client_id=764086051850-6qr4p6gpi6hn506pt8ejuq83di341hur.apps.googleusercontent.com&scope=openid+https%3A%2F%2Fwww.googleapis.com%2Fauth%2Fuserinfo.email+https%3A%2F%2Fwww.googleapis.com%2Fauth%2Fcloud-platform+https%3A%2F%2Fwww.googleapis.com%2Fauth%2Faccounts.reauth&state=kZnlRO6sCkvrlcSZSz3vNK77cZAGfQ&access_type=offline&code_challenge=o6u0LFEvEZ5RG6EmiZFzEUFKTorxdf1GPkuwY7_XV_c&code_challenge_method=S256&token_usage=remote"

2022-05-12 07:11:01,183 INFO     ___FILE_ONLY___ 


2022-05-12 07:11:34,149 ERROR    root            There was a problem with web authentication.
2022-05-12 07:11:34,149 DEBUG    root            (gcloud.auth.application-default.login) The provided authorization response is invalid. Expect a url with query parameters of [state, code, scope].
Traceback (most recent call last):
  File "/usr/lib64/google-cloud-sdk/lib/googlecloudsdk/calliope/cli.py", line 987, in Execute
    resources = calliope_command.Run(cli=self, args=args)
  File "/usr/lib64/google-cloud-sdk/lib/googlecloudsdk/calliope/backend.py", line 809, in Run
    resources = command_instance.Run(args)
  File "/usr/lib64/google-cloud-sdk/lib/surface/auth/application_default/login.py", line 137, in Run
    creds = auth_util.DoInstalledAppBrowserFlowGoogleAuth(
  File "/usr/lib64/google-cloud-sdk/lib/googlecloudsdk/api_lib/auth/util.py", line 303, in DoInstalledAppBrowserFlowGoogleAuth
    user_creds = NoBrowserFlowRunner(scopes, client_config).Run()
  File "/usr/lib64/google-cloud-sdk/lib/googlecloudsdk/api_lib/auth/util.py", line 138, in Run
    return self._flow.Run(**kwargs)
  File "/usr/lib64/google-cloud-sdk/lib/googlecloudsdk/core/credentials/flow.py", line 231, in Run
    return self._Run(**kwargs)
  File "/usr/lib64/google-cloud-sdk/lib/googlecloudsdk/core/credentials/flow.py", line 542, in _Run
    _ValidateAuthResponse(auth_response)
  File "/usr/lib64/google-cloud-sdk/lib/googlecloudsdk/core/credentials/flow.py", line 470, in _ValidateAuthResponse
    raise AuthRequestFailedError(_AUTH_RESPONSE_ERR_MSG)
googlecloudsdk.core.credentials.flow.AuthRequestFailedError: The provided authorization response is invalid. Expect a url with query parameters of [state, code, scope].
2022-05-12 07:11:34,152 ERROR    root            (gcloud.auth.application-default.login) The provided authorization response is invalid. Expect a url with query parameters of [state, code, scope].
